Workbook

Sheet 展示
A1: 公益1组 | E1: 公益2组 | I1: 创意1组 | M1: 创意2组 | Q1: 创意3组
A2: 学校 | B2: 项目名称 | C2: 得分 | D2: 名次 | E2: 学校 | F2: 项目名称 | G2: 得分 | H2: 名次 | I2: 学校 | J2: 项目名称 | K2: 得分 | L2: 名次 | M2: 学校 | N2: 项目名称 | O2: 得分 | P2: 名次 | Q2: 学校 | R2: 项目名称 | S2: 得分 | T2: 名次
A3: =VLOOKUP(B3,路演答辩顺序!$A:$B,2,FALSE) -> 南京工业大学 | B3: =OFFSET(手动更新!$A$2,(ROW(A1)-1)*4,0) -> 垒球冠军计划—青少年垒球运动公益推广的引领者 | C3: =OFFSET(手动更新!$A$3,(ROW(A1)-1)*4,0) -> 89.6 | D3: =OFFSET(手动更新!$A$4,(ROW(C1)-1)*4,0) -> 第1名 | E3: =VLOOKUP(F3,路演答辩顺序!$A:$B,2,FALSE) -> 河海大学 | F3: =OFFSET(手动更新!$B$2,(ROW(E1)-1)*4,0) -> 沧海补蛎—海岸带保护修复先锋 | G3: =OFFSET(手动更新!$B$3,(ROW(E1)-1)*4,0) -> 89.97 | H3: =OFFSET(手动更新!$A$4,(ROW(G1)-1)*4,0) -> 第1名 | I3: =VLOOKUP(J3,路演答辩顺序!$A:$B,2,FALSE) -> 南京大学 | J3: =OFFSET(手动更新!$C$2,(ROW(I1)-1)*4,0) -> 沙漠里的家——为三百万戈壁牧民 焕新北疆生态牧居 | K3: =OFFSET(手动更新!$C$3,(ROW(I1)-1)*4,0) -> 89.03 | L3: =OFFSET(手动更新!$C$4,(ROW(K1)-1)*4,0) -> 第1名 | M3: =VLOOKUP(N3,路演答辩顺序!$A:$B,2,FALSE) -> 南京工业大学 | N3: =OFFSET(手动更新!$D$2,(ROW(M1)-1)*4,0) -> 科锐智气——特种气体精密测控装置破局者 | O3: =OFFSET(手动更新!$D$3,(ROW(M1)-1)*4,0) -> 89.56 | P3: =OFFSET(手动更新!$D$4,(ROW(O1)-1)*4,0) -> 第1名 | Q3: =VLOOKUP(R3,路演答辩顺序!$A:$B,2,FALSE) -> 苏州工学院 | R3: =OFFSET(手动更新!$E$2,(ROW(Q1)-1)*4,0) -> 鳞烯双致——石墨烯/玻璃鳞片协同长效海洋防腐涂层创新者 | S3: =OFFSET(手动更新!$E$3,(ROW(Q1)-1)*4,0) -> 89.09 | T3: =OFFSET(手动更新!$E$4,(ROW(S1)-1)*4,0) -> 第1名
A4: =VLOOKUP(B4,路演答辩顺序!$A:$B,2,FALSE) -> 南京工业职业技术大学 | B4: =OFFSET(手动更新!$A$2,(ROW(A2)-1)*4,0) -> 铭记你的名字——助力烈士“回家”新标杆 | C4: =OFFSET(手动更新!$A$3,(ROW(A2)-1)*4,0) -> 88.63 | D4: =OFFSET(手动更新!$A$4,(ROW(C2)-1)*4,0) -> 第2名 | E4: =VLOOKUP(F4,路演答辩顺序!$A:$B,2,FALSE) -> 南京大学 | F4: =OFFSET(手动更新!$B$2,(ROW(E2)-1)*4,0) -> 青联世界 | G4: =OFFSET(手动更新!$B$3,(ROW(E2)-1)*4,0) -> 89.71 | H4: =OFFSET(手动更新!$A$4,(ROW(G2)-1)*4,0) -> 第2名 | I4: =VLOOKUP(J4,路演答辩顺序!$A:$B,2,FALSE) -> 南京工业大学 | J4: =OFFSET(手动更新!$C$2,(ROW(I2)-1)*4,0) -> 光合零碳——全蒸镀钙钛矿光伏补光一体化智慧农业温室 | K4: =OFFSET(手动更新!$C$3,(ROW(I2)-1)*4,0) -> 88.17 | L4: =OFFSET(手动更新!$C$4,(ROW(K2)-1)*4,0) -> 第2名 | M4: =VLOOKUP(N4,路演答辩顺序!$A:$B,2,FALSE) -> 南京航空航天大学 | N4: =OFFSET(手动更新!$D$2,(ROW(M2)-1)*4,0) -> 智启凌空——集群智能决策模型虚实迁移技术开拓者 | O4: =OFFSET(手动更新!$D$3,(ROW(M2)-1)*4,0) -> 88.97 | P4: =OFFSET(手动更新!$D$4,(ROW(O2)-1)*4,0) -> 第2名 | Q4: =VLOOKUP(R4,路演答辩顺序!$A:$B,2,FALSE) -> 南京林业大学 | R4: =OFFSET(手动更新!$E$2,(ROW(Q2)-1)*4,0) -> 见微知竹-打破高端垄断的绿色竹基微晶纤维素 | S4: =OFFSET(手动更新!$E$3,(ROW(Q2)-1)*4,0) -> 88.81 | T4: =OFFSET(手动更新!$E$4,(ROW(S2)-1)*4,0) -> 第2名
A5: =VLOOKUP(B5,路演答辩顺序!$A:$B,2,FALSE) -> 河海大学 | B5: =OFFSET(手动更新!$A$2,(ROW(A3)-1)*4,0) -> 智润九曲——借数智慧脑破千库调度难题，引一河清流润泽沿黄万家 | C5: =OFFSET(手动更新!$A$3,(ROW(A3)-1)*4,0) -> 87.49 | D5: =OFFSET(手动更新!$A$4,(ROW(C3)-1)*4,0) -> 第3名 | E5: =VLOOKUP(F5,路演答辩顺序!$A:$B,2,FALSE) -> 东南大学 | F5: =OFFSET(手动更新!$B$2,(ROW(E3)-1)*4,0) -> 牡丹春动育新声——古老昆曲的青春故事：让昆曲“曲高不和寡” | G5: =OFFSET(手动更新!$B$3,(ROW(E3)-1)*4,0) -> 89.31 | H5: =OFFSET(手动更新!$A$4,(ROW(G3)-1)*4,0) -> 第3名 | I5: =VLOOKUP(J5,路演答辩顺序!$A:$B,2,FALSE) -> 南京理工大学 | J5: =OFFSET(手动更新!$C$2,(ROW(I3)-1)*4,0) -> 帧相——AI焕新历史影像，赓续精神血脉 | K5: =OFFSET(手动更新!$C$3,(ROW(I3)-1)*4,0) -> 88.03 | L5: =OFFSET(手动更新!$C$4,(ROW(K3)-1)*4,0) -> 第3名 | M5: =VLOOKUP(N5,路演答辩顺序!$A:$B,2,FALSE) -> 南京医科大学 | N5: =OFFSET(手动更新!$D$2,(ROW(M3)-1)*4,0) -> 肾利者——尿液驱动肾癌“早筛-精准递送”一体化解决方案 | O5: =OFFSET(手动更新!$D$3,(ROW(M3)-1)*4,0) -> 87.44 | P5: =OFFSET(手动更新!$D$4,(ROW(O3)-1)*4,0) -> 第3名 | Q5: =VLOOKUP(R5,路演答辩顺序!$A:$B,2,FALSE) -> 南京医科大学 | R5: =OFFSET(手动更新!$E$2,(ROW(Q3)-1)*4,0) -> 丹芯——耐药菌快速药敏数字芯片领航者 | S5: =OFFSET(手动更新!$E$3,(ROW(Q3)-1)*4,0) -> 88 | T5: =OFFSET(手动更新!$E$4,(ROW(S3)-1)*4,0) -> 第3名
A6: =VLOOKUP(B6,路演答辩顺序!$A:$B,2,FALSE) -> 扬州工业职业技术学院 | B6: =OFFSET(手动更新!$A$2,(ROW(A4)-1)*4,0) -> 救·在身边 | C6: =OFFSET(手动更新!$A$3,(ROW(A4)-1)*4,0) -> 86.44 | D6: =OFFSET(手动更新!$A$4,(ROW(C4)-1)*4,0) -> 第4名 | E6: =VLOOKUP(F6,路演答辩顺序!$A:$B,2,FALSE) -> 南京师范大学 | F6: =OFFSET(手动更新!$B$2,(ROW(E4)-1)*4,0) -> 扣响未来——传承中国女排精神新力量 创领大众排球运动新生态 | G6: =OFFSET(手动更新!$B$3,(ROW(E4)-1)*4,0) -> 87.73 | H6: =OFFSET(手动更新!$A$4,(ROW(G4)-1)*4,0) -> 第4名 | I6: =VLOOKUP(J6,路演答辩顺序!$A:$B,2,FALSE) -> 江苏大学 | J6: =OFFSET(手动更新!$C$2,(ROW(I4)-1)*4,0) -> 稻富万家——农机农艺赋能再生稻振兴计划，提质增产助农增收 | K6: =OFFSET(手动更新!$C$3,(ROW(I4)-1)*4,0) -> 86.8 | L6: =OFFSET(手动更新!$C$4,(ROW(K4)-1)*4,0) -> 第4名 | M6: =VLOOKUP(N6,路演答辩顺序!$A:$B,2,FALSE) -> 扬州大学 | N6: =OFFSET(手动更新!$D$2,(ROW(M4)-1)*4,0) -> 见微知著——超分辨电化学发光显微成像模块 | O6: =OFFSET(手动更新!$D$3,(ROW(M4)-1)*4,0) -> 87.39 | P6: =OFFSET(手动更新!$D$4,(ROW(O4)-1)*4,0) -> 第4名 | Q6: =VLOOKUP(R6,路演答辩顺序!$A:$B,2,FALSE) -> 南京信息工程大学 | R6: =OFFSET(手动更新!$E$2,(ROW(Q4)-1)*4,0) -> 光芯智连——新一代AI智算中心光互连集成芯片 | S6: =OFFSET(手动更新!$E$3,(ROW(Q4)-1)*4,0) -> 87.09 | T6: =OFFSET(手动更新!$E$4,(ROW(S4)-1)*4,0) -> 第4名
A7: =VLOOKUP(B7,路演答辩顺序!$A:$B,2,FALSE) -> 江苏航运职业技术学院 | B7: =OFFSET(手动更新!$A$2,(ROW(A5)-1)*4,0) -> 无毒有偶——青少年禁毒公益新生态构建者 | C7: =OFFSET(手动更新!$A$3,(ROW(A5)-1)*4,0) -> 86.27 | D7: =OFFSET(手动更新!$A$4,(ROW(C5)-1)*4,0) -> 第5名 | E7: =VLOOKUP(F7,路演答辩顺序!$A:$B,2,FALSE) -> 常州大学 | F7: =OFFSET(手动更新!$B$2,(ROW(E5)-1)*4,0) -> 归途明灯——涉罪青少年矫正与成长引航 | G7: =OFFSET(手动更新!$B$3,(ROW(E5)-1)*4,0) -> 86.51 | H7: =OFFSET(手动更新!$A$4,(ROW(G5)-1)*4,0) -> 第5名 | I7: =VLOOKUP(J7,路演答辩顺序!$A:$B,2,FALSE) -> 南京师范大学 | J7: =OFFSET(手动更新!$C$2,(ROW(I5)-1)*4,0) -> 乡村鸿雁——合成生物学引领赤霉素GA4国际领先践行农业强国 | K7: =OFFSET(手动更新!$C$3,(ROW(I5)-1)*4,0) -> 85.63 | L7: =OFFSET(手动更新!$C$4,(ROW(K5)-1)*4,0) -> 第5名 | M7: =VLOOKUP(N7,路演答辩顺序!$A:$B,2,FALSE) -> 徐州医科大学 | N7: =OFFSET(手动更新!$D$2,(ROW(M5)-1)*4,0) -> 肠有灵硒——结直肠癌放疗增敏与放射损伤保护一体化治疗推动者 | O7: =OFFSET(手动更新!$D$3,(ROW(M5)-1)*4,0) -> 86.17 | P7: =OFFSET(手动更新!$D$4,(ROW(O5)-1)*4,0) -> 第5名 | Q7: =VLOOKUP(R7,路演答辩顺序!$A:$B,2,FALSE) -> 河海大学 | R7: =OFFSET(手动更新!$E$2,(ROW(Q5)-1)*4,0) -> 慧谱清源——水环境高光谱智能监测领航者 | S7: =OFFSET(手动更新!$E$3,(ROW(Q5)-1)*4,0) -> 87.07 | T7: =OFFSET(手动更新!$E$4,(ROW(S5)-1)*4,0) -> 第5名
A8: =VLOOKUP(B8,路演答辩顺序!$A:$B,2,FALSE) -> 南京航空航天大学 | B8: =OFFSET(手动更新!$A$2,(ROW(A6)-1)*4,0) -> 智育星火—AI赋能新时代青少年国防教育 | C8: =OFFSET(手动更新!$A$3,(ROW(A6)-1)*4,0) -> 86.07 | D8: =OFFSET(手动更新!$A$4,(ROW(C6)-1)*4,0) -> 第6名 | E8: =VLOOKUP(F8,路演答辩顺序!$A:$B,2,FALSE) -> 南京理工大学 | F8: =OFFSET(手动更新!$B$2,(ROW(E6)-1)*4,0) -> 永远的丰碑——隐蔽战线英烈档案挖掘、保护与传播 | G8: =OFFSET(手动更新!$B$3,(ROW(E6)-1)*4,0) -> 85.94 | H8: =OFFSET(手动更新!$A$4,(ROW(G6)-1)*4,0) -> 第6名 | I8: =VLOOKUP(J8,路演答辩顺序!$A:$B,2,FALSE) -> 南京农业大学 | J8: =OFFSET(手动更新!$C$2,(ROW(I6)-1)*4,0) -> 育优莓，兴万农——以创新有机肥助力蓝莓产业富农兴农 | K8: =OFFSET(手动更新!$C$3,(ROW(I6)-1)*4,0) -> 85.23 | L8: =OFFSET(手动更新!$C$4,(ROW(K6)-1)*4,0) -> 第6名 | M8: =VLOOKUP(N8,路演答辩顺序!$A:$B,2,FALSE) -> 江苏科技大学 | N8: =OFFSET(手动更新!$D$2,(ROW(M6)-1)*4,0) -> 智焊无界——大型船舶超厚板智能焊接装备领航者 | O8: =OFFSET(手动更新!$D$3,(ROW(M6)-1)*4,0) -> 85.87 | P8: =OFFSET(手动更新!$D$4,(ROW(O6)-1)*4,0) -> 第6名 | Q8: =VLOOKUP(R8,路演答辩顺序!$A:$B,2,FALSE) -> 江苏食品药品职业技术学院 | R8: =OFFSET(手动更新!$E$2,(ROW(Q6)-1)*4,0) -> “臻”芯无虞——超高保真分子诊断预混液国产领航者 | S8: =OFFSET(手动更新!$E$3,(ROW(Q6)-1)*4,0) -> 86.04 | T8: =OFFSET(手动更新!$E$4,(ROW(S6)-1)*4,0) -> 第6名
A9: =VLOOKUP(B9,路演答辩顺序!$A:$B,2,FALSE) -> 河海大学 | B9: =OFFSET(手动更新!$A$2,(ROW(A7)-1)*4,0) -> 法润电商--法律服务赋能农村电商助力乡村振兴 | C9: =OFFSET(手动更新!$A$3,(ROW(A7)-1)*4,0) -> 85.19 | D9: =OFFSET(手动更新!$A$4,(ROW(C7)-1)*4,0) -> 第7名 | E9: =VLOOKUP(F9,路演答辩顺序!$A:$B,2,FALSE) -> 南京信息工程大学 | F9: =OFFSET(手动更新!$B$2,(ROW(E7)-1)*4,0) -> 工脉铸魂——红色工业文化“三阶”育人推动者 | G9: =OFFSET(手动更新!$B$3,(ROW(E7)-1)*4,0) -> 85.34 | H9: =OFFSET(手动更新!$A$4,(ROW(G7)-1)*4,0) -> 第7名 | I9: =VLOOKUP(J9,路演答辩顺序!$A:$B,2,FALSE) -> 南京林业大学 | J9: =OFFSET(手动更新!$C$2,(ROW(I7)-1)*4,0) -> 出漆智胜——高效智能割漆机器人 助力漆农减负与漆产业发展 | K9: =OFFSET(手动更新!$C$3,(ROW(I7)-1)*4,0) -> 85.03 | L9: =OFFSET(手动更新!$C$4,(ROW(K7)-1)*4,0) -> 第7名 | M9: =VLOOKUP(N9,路演答辩顺序!$A:$B,2,FALSE) -> 南京农业大学 | N9: =OFFSET(手动更新!$D$2,(ROW(M7)-1)*4,0) -> 碳寻新剂—国内首创菌渣基药肥一体化肥料添加剂 | O9: =OFFSET(手动更新!$D$3,(ROW(M7)-1)*4,0) -> 85.44 | P9: =OFFSET(手动更新!$D$4,(ROW(O7)-1)*4,0) -> 第7名 | Q9: =VLOOKUP(R9,路演答辩顺序!$A:$B,2,FALSE) -> 常州大学 | R9: =OFFSET(手动更新!$E$2,(ROW(Q7)-1)*4,0) -> 智声慧检——用于城镇埋地燃气管道的智能声学内检测器 | S9: =OFFSET(手动更新!$E$3,(ROW(Q7)-1)*4,0) -> 84.91 | T9: =OFFSET(手动更新!$E$4,(ROW(S7)-1)*4,0) -> 第7名
A10: =VLOOKUP(B10,路演答辩顺序!$A:$B,2,FALSE) -> 苏州大学 | B10: =OFFSET(手动更新!$A$2,(ROW(A8)-1)*4,0) -> 铁军薪火：海外新四军抗战档案抢救整理与红色基因传承新范式 | C10: =OFFSET(手动更新!$A$3,(ROW(A8)-1)*4,0) -> 84.73 | D10: =OFFSET(手动更新!$A$4,(ROW(C8)-1)*4,0) -> 第8名 | E10: =VLOOKUP(F10,路演答辩顺序!$A:$B,2,FALSE) -> 宿迁学院 | F10: =OFFSET(手动更新!$B$2,(ROW(E8)-1)*4,0) -> 逐光而行——以京东“阳光天使”为起点的新业态下助残就业新路径 | G10: =OFFSET(手动更新!$B$3,(ROW(E8)-1)*4,0) -> 83.41 | H10: =OFFSET(手动更新!$A$4,(ROW(G8)-1)*4,0) -> 第8名 | I10: =VLOOKUP(J10,路演答辩顺序!$A:$B,2,FALSE) -> 淮阴师范学院 | J10: =OFFSET(手动更新!$C$2,(ROW(I8)-1)*4,0) -> 稻香菇事——轮作兴农乡村振兴力行者 | K10: =OFFSET(手动更新!$C$3,(ROW(I8)-1)*4,0) -> 84.13 | L10: =OFFSET(手动更新!$C$4,(ROW(K8)-1)*4,0) -> 第8名 | M10: =VLOOKUP(N10,路演答辩顺序!$A:$B,2,FALSE) -> 苏州工学院 | N10: =OFFSET(手动更新!$D$2,(ROW(M8)-1)*4,0) -> 鉴布如飞—新一代柔性全景自增强织造检测高效随诊师 | O10: =OFFSET(手动更新!$D$3,(ROW(M8)-1)*4,0) -> 84.51 | P10: =OFFSET(手动更新!$D$4,(ROW(O8)-1)*4,0) -> 第8名 | Q10: =VLOOKUP(R10,路演答辩顺序!$A:$B,2,FALSE) -> 无锡学院 | R10: =OFFSET(手动更新!$E$2,(ROW(Q8)-1)*4,0) -> 信安哨兵——地铁插拔式信号设备智能安全预检系统 | S10: =OFFSET(手动更新!$E$3,(ROW(Q8)-1)*4,0) -> 84.77 | T10: =OFFSET(手动更新!$E$4,(ROW(S8)-1)*4,0) -> 第8名
A11: =VLOOKUP(B11,路演答辩顺序!$A:$B,2,FALSE) -> 江苏城市职业学院 | B11: =OFFSET(手动更新!$A$2,(ROW(A9)-1)*4,0) -> 有爱无碍，赋能残疾人共享社会发展成果 | C11: =OFFSET(手动更新!$A$3,(ROW(A9)-1)*4,0) -> 83.21 | D11: =OFFSET(手动更新!$A$4,(ROW(C9)-1)*4,0) -> 第9名 | E11: =VLOOKUP(F11,路演答辩顺序!$A:$B,2,FALSE) -> 苏州科技大学 | F11: =OFFSET(手动更新!$B$2,(ROW(E9)-1)*4,0) -> 人间重晚晴——守护生命最后一公里的“尊严” | G11: =OFFSET(手动更新!$B$3,(ROW(E9)-1)*4,0) -> 83.16 | H11: =OFFSET(手动更新!$A$4,(ROW(G9)-1)*4,0) -> 第9名 | I11: =VLOOKUP(J11,路演答辩顺序!$A:$B,2,FALSE) -> 南京铁道职业技术学院 | J11: =OFFSET(手动更新!$C$2,(ROW(I9)-1)*4,0) -> 红途戎耀——退役大学生国防教育赋能计划 | K11: =OFFSET(手动更新!$C$3,(ROW(I9)-1)*4,0) -> 83.09 | L11: =OFFSET(手动更新!$C$4,(ROW(K9)-1)*4,0) -> 第9名 | M11: =VLOOKUP(N11,路演答辩顺序!$A:$B,2,FALSE) -> 无锡学院 | N11: =OFFSET(手动更新!$D$2,(ROW(M9)-1)*4,0) -> 慧眼鉴晶-晶圆异常针痕及表面缺陷检测领航者 | O11: =OFFSET(手动更新!$D$3,(ROW(M9)-1)*4,0) -> 83.79 | P11: =OFFSET(手动更新!$D$4,(ROW(O9)-1)*4,0) -> 第9名 | Q11: =VLOOKUP(R11,路演答辩顺序!$A:$B,2,FALSE) -> 扬州大学 | R11: =OFFSET(手动更新!$E$2,(ROW(Q9)-1)*4,0) -> 藻豆生鲜—新型藻豆复合蛋白基料引领者 | S11: =OFFSET(手动更新!$E$3,(ROW(Q9)-1)*4,0) -> 84.27 | T11: =OFFSET(手动更新!$E$4,(ROW(S9)-1)*4,0) -> 第9名
A12: =VLOOKUP(B12,路演答辩顺序!$A:$B,2,FALSE) -> 南京铁道职业技术学院 | B12: =OFFSET(手动更新!$A$2,(ROW(A10)-1)*4,0) -> 铁脉薪传—铁道兵精神传承专列 | C12: =OFFSET(手动更新!$A$3,(ROW(A10)-1)*4,0) -> 82.61 | D12: =OFFSET(手动更新!$A$4,(ROW(C10)-1)*4,0) -> 第10名 | E12: =VLOOKUP(F12,路演答辩顺序!$A:$B,2,FALSE) -> 南京铁道职业技术学院 | F12: =OFFSET(手动更新!$B$2,(ROW(E10)-1)*4,0) -> 橙光智愿——全国首个铁路志愿全周期赋能学堂 | G12: =OFFSET(手动更新!$B$3,(ROW(E10)-1)*4,0) -> 82.01 | H12: =OFFSET(手动更新!$A$4,(ROW(G10)-1)*4,0) -> 第10名 | I12: =VLOOKUP(J12,路演答辩顺序!$A:$B,2,FALSE) -> 江苏航运职业技术学院 | J12: =OFFSET(手动更新!$C$2,(ROW(I10)-1)*4,0) -> 忆海拾贝 钿启新航——非遗螺钿的幻彩新生 | K12: =OFFSET(手动更新!$C$3,(ROW(I10)-1)*4,0) -> 82.53 | L12: =OFFSET(手动更新!$C$4,(ROW(K10)-1)*4,0) -> 第10名 | M12: =VLOOKUP(N12,路演答辩顺序!$A:$B,2,FALSE) -> 江苏海洋大学 | N12: =OFFSET(手动更新!$D$2,(ROW(M10)-1)*4,0) -> 热控凉方——高集成封装芯片散热用高导热界面材料 | O12: =OFFSET(手动更新!$D$3,(ROW(M10)-1)*4,0) -> 83 | P12: =OFFSET(手动更新!$D$4,(ROW(O10)-1)*4,0) -> 第10名 | Q12: =VLOOKUP(R12,路演答辩顺序!$A:$B,2,FALSE) -> 徐州工程学院 | R12: =OFFSET(手动更新!$E$2,(ROW(Q10)-1)*4,0) -> 深地之眼—隧洞施工多技术融合智能探测模块践行者 | S12: =OFFSET(手动更新!$E$3,(ROW(Q10)-1)*4,0) -> 83.39 | T12: =OFFSET(手动更新!$E$4,(ROW(S10)-1)*4,0) -> 第10名
A13: =VLOOKUP(B13,路演答辩顺序!$A:$B,2,FALSE) -> 苏州健雄职业技术学院 | B13: =OFFSET(手动更新!$A$2,(ROW(A11)-1)*4,0) -> “骑”心协力“救”在身边——快递外卖从业者急救素养提升公益行动 | C13: =OFFSET(手动更新!$A$3,(ROW(A11)-1)*4,0) -> 80.3 | D13: =OFFSET(手动更新!$A$4,(ROW(C11)-1)*4,0) -> 第11名 | E13: =VLOOKUP(F13,路演答辩顺序!$A:$B,2,FALSE) -> 江苏农牧科技职业学院 | F13: =OFFSET(手动更新!$B$2,(ROW(E11)-1)*4,0) -> 青春π先锋公益——关爱留守儿童，让心不再孤单 | G13: =OFFSET(手动更新!$B$3,(ROW(E11)-1)*4,0) -> 80.84 | H13: =OFFSET(手动更新!$A$4,(ROW(G11)-1)*4,0) -> 第11名 | I13: =VLOOKUP(J13,路演答辩顺序!$A:$B,2,FALSE) -> 江苏工程职业技术学院 | J13: =OFFSET(手动更新!$C$2,(ROW(I11)-1)*4,0) -> 光净清源——有机毒害污水激光空化降解缔造者 | K13: =OFFSET(手动更新!$C$3,(ROW(I11)-1)*4,0) -> 82.23 | L13: =OFFSET(手动更新!$C$4,(ROW(K11)-1)*4,0) -> 第11名 | M13: =VLOOKUP(N13,路演答辩顺序!$A:$B,2,FALSE) -> 徐州工程学院 | N13: =OFFSET(手动更新!$D$2,(ROW(M11)-1)*4,0) -> 工业智瞳——新时代高水平工业智能装备软件AI测试安全守护者 | O13: =OFFSET(手动更新!$D$3,(ROW(M11)-1)*4,0) -> 82.44 | P13: =OFFSET(手动更新!$D$4,(ROW(O11)-1)*4,0) -> 第11名 | Q13: =VLOOKUP(R13,路演答辩顺序!$A:$B,2,FALSE) -> 江苏师范大学 | R13: =OFFSET(手动更新!$E$2,(ROW(Q11)-1)*4,0) -> 星驭——面向卫星互联网激光通信的2μm智能化种子源 | S13: =OFFSET(手动更新!$E$3,(ROW(Q11)-1)*4,0) -> 82.17 | T13: =OFFSET(手动更新!$E$4,(ROW(S11)-1)*4,0) -> 第11名
A14: =VLOOKUP(B14,路演答辩顺序!$A:$B,2,FALSE) -> #N/A | B14: =OFFSET(手动更新!$A$2,(ROW(A12)-1)*4,0) -> 0 | C14: =OFFSET(手动更新!$A$3,(ROW(A12)-1)*4,0) -> 0 | D14: =OFFSET(手动更新!$A$4,(ROW(C12)-1)*4,0) -> 0 | E14: =VLOOKUP(F14,路演答辩顺序!$A:$B,2,FALSE) -> #N/A | F14: =OFFSET(手动更新!$B$2,(ROW(E12)-1)*4,0) -> 0 | G14: =OFFSET(手动更新!$B$3,(ROW(E12)-1)*4,0) -> 0 | H14: =OFFSET(手动更新!$A$4,(ROW(G12)-1)*4,0) -> 0 | I14: =VLOOKUP(J14,路演答辩顺序!$A:$B,2,FALSE) -> #N/A | J14: =OFFSET(手动更新!$C$2,(ROW(I12)-1)*4,0) -> 0 | K14: =OFFSET(手动更新!$C$3,(ROW(I12)-1)*4,0) -> 0 | L14: =OFFSET(手动更新!$C$4,(ROW(K12)-1)*4,0) -> 0 | M14: =VLOOKUP(N14,路演答辩顺序!$A:$B,2,FALSE) -> 苏州工学院 | N14: =OFFSET(手动更新!$D$2,(ROW(M12)-1)*4,0) -> 创芯速鉴-高标准快检护航果蔬无忧出海 | O14: =OFFSET(手动更新!$D$3,(ROW(M12)-1)*4,0) -> 81.77 | P14: =OFFSET(手动更新!$D$4,(ROW(O12)-1)*4,0) -> 第12名 | Q14: =VLOOKUP(R14,路演答辩顺序!$A:$B,2,FALSE) -> #N/A | R14: =OFFSET(手动更新!$E$2,(ROW(Q12)-1)*4,0) -> 0 | S14: =OFFSET(手动更新!$E$3,(ROW(Q12)-1)*4,0) -> 0 | T14: =OFFSET(手动更新!$E$4,(ROW(S12)-1)*4,0) -> 0
... A28: =VLOOKUP(B28,路演答辩顺序!$A:$B,2,FALSE) -> #N/A | B28: =OFFSET(手动更新!$A$2,(ROW(A26)-1)*4,0) -> 0 | C28: =OFFSET(手动更新!$A$3,(ROW(A26)-1)*4,0) -> 0 | D28: =OFFSET(手动更新!$A$4,(ROW(C26)-1)*4,0) -> 0 | E28: =VLOOKUP(F28,路演答辩顺序!$A:$B,2,FALSE) -> #N/A | F28: =OFFSET(手动更新!$B$2,(ROW(E26)-1)*4,0) -> 0 | G28: =OFFSET(手动更新!$B$3,(ROW(E26)-1)*4,0) -> 0 | H28: =OFFSET(手动更新!$A$4,(ROW(G26)-1)*4,0) -> 0 | I28: =VLOOKUP(J28,路演答辩顺序!$A:$B,2,FALSE) -> #N/A | J28: =OFFSET(手动更新!$C$2,(ROW(I26)-1)*4,0) -> 0 | K28: =OFFSET(手动更新!$C$3,(ROW(I26)-1)*4,0) -> 0 | L28: =OFFSET(手动更新!$C$4,(ROW(K26)-1)*4,0) -> 0 | M28: =VLOOKUP(N28,路演答辩顺序!$A:$B,2,FALSE) -> #N/A | N28: =OFFSET(手动更新!$D$2,(ROW(M26)-1)*4,0) -> 0 | O28: =OFFSET(手动更新!$D$3,(ROW(M26)-1)*4,0) -> 0 | P28: =OFFSET(手动更新!$D$4,(ROW(O26)-1)*4,0) -> 0 | Q28: =VLOOKUP(R28,路演答辩顺序!$A:$B,2,FALSE) -> #N/A | R28: =OFFSET(手动更新!$E$2,(ROW(Q26)-1)*4,0) -> 0 | S28: =OFFSET(手动更新!$E$3,(ROW(Q26)-1)*4,0) -> 0 | T28: =OFFSET(手动更新!$E$4,(ROW(S26)-1)*4,0) -> 0

Sheet 手动更新
A1: 9 | B1: 8 | C1: 6 | D1: 10 | E1: 7
A2: 垒球冠军计划—青少年垒球运动公益推广的引领者 | B2: 沧海补蛎—海岸带保护修复先锋 | C2: 沙漠里的家——为三百万戈壁牧民 焕新北疆生态牧居 | D2: 科锐智气——特种气体精密测控装置破局者 | E2: 鳞烯双致——石墨烯/玻璃鳞片协同长效海洋防腐涂层创新者
A3: 89.6 | B3: 89.97 | C3: 89.03 | D3: 89.56 | E3: 89.09
A4: 第1名 | B4: 第1名 | C4: 第1名 | D4: 第1名 | E4: 第1名
A5: 3 | B5: 11 | C5: 4 | D5: 12 | E5: 4
A6: 铭记你的名字——助力烈士“回家”新标杆 | B6: 青联世界 | C6: 光合零碳——全蒸镀钙钛矿光伏补光一体化智慧农业温室 | D6: 智启凌空——集群智能决策模型虚实迁移技术开拓者 | E6: 见微知竹-打破高端垄断的绿色竹基微晶纤维素
A7: 88.63 | B7: 89.71 | C7: 88.17 | D7: 88.97 | E7: 88.81
A8: 第2名 | B8: 第2名 | C8: 第2名 | D8: 第2名 | E8: 第2名
A9: 8 | B9: 9 | C9: 9 | D9: 4 | E9: 8
A10: 智润九曲——借数智慧脑破千库调度难题，引一河清流润泽沿黄万家 | B10: 牡丹春动育新声——古老昆曲的青春故事：让昆曲“曲高不和寡” | C10: 帧相——AI焕新历史影像，赓续精神血脉 | D10: 肾利者——尿液驱动肾癌“早筛-精准递送”一体化解决方案 | E10: 丹芯——耐药菌快速药敏数字芯片领航者
A11: 87.49 | B11: 89.31 | C11: 88.03 | D11: 87.44 | E11: 88
A12: 第3名 | B12: 第3名 | C12: 第3名 | D12: 第3名 | E12: 第3名
A13: 1 | B13: 5 | C13: 11 | D13: 6 | E13: 11
A14: 救·在身边 | B14: 扣响未来——传承中国女排精神新力量 创领大众排球运动新生态 | C14: 稻富万家——农机农艺赋能再生稻振兴计划，提质增产助农增收 | D14: 见微知著——超分辨电化学发光显微成像模块 | E14: 光芯智连——新一代AI智算中心光互连集成芯片
A15: 86.44 | B15: 87.73 | C15: 86.8 | D15: 87.39 | E15: 87.09
A16: 第4名 | B16: 第4名 | C16: 第4名 | D16: 第4名 | E16: 第4名
A17: 4 | B17: 1 | C17: 8 | D17: 1 | E17: 1
A18: 无毒有偶——青少年禁毒公益新生态构建者 | B18: 归途明灯——涉罪青少年矫正与成长引航 | C18: 乡村鸿雁——合成生物学引领赤霉素GA4国际领先践行农业强国 | D18: 肠有灵硒——结直肠癌放疗增敏与放射损伤保护一体化治疗推动者 | E18: 慧谱清源——水环境高光谱智能监测领航者
A19: 86.27 | B19: 86.51 | C19: 85.63 | D19: 86.17 | E19: 87.07
A20: 第5名 | B20: 第5名 | C20: 第5名 | D20: 第5名 | E20: 第5名
A21: 7 | B21: 4 | C21: 7 | D21: 5 | E21: 10
A22: 智育星火—AI赋能新时代青少年国防教育 | B22: 永远的丰碑——隐蔽战线英烈档案挖掘、保护与传播 | C22: 育优莓，兴万农——以创新有机肥助力蓝莓产业富农兴农 | D22: 智焊无界——大型船舶超厚板智能焊接装备领航者 | E22: “臻”芯无虞——超高保真分子诊断预混液国产领航者
A23: 86.07 | B23: 85.94 | C23: 85.23 | D23: 85.87 | E23: 86.04
A24: 第6名 | B24: 第6名 | C24: 第6名 | D24: 第6名 | E24: 第6名
A25: 10 | B25: 7 | C25: 5 | D25: 7 | E25: 9
A26: 法润电商--法律服务赋能农村电商助力乡村振兴 | B26: 工脉铸魂——红色工业文化“三阶”育人推动者 | C26: 出漆智胜——高效智能割漆机器人 助力漆农减负与漆产业发展 | D26: 碳寻新剂—国内首创菌渣基药肥一体化肥料添加剂 | E26: 智声慧检——用于城镇埋地燃气管道的智能声学内检测器
A27: 85.19 | B27: 85.34 | C27: 85.03 | D27: 85.44 | E27: 84.91
A28: 第7名 | B28: 第7名 | C28: 第7名 | D28: 第7名 | E28: 第7名
A29: 11 | B29: 10 | C29: 10 | D29: 9 | E29: 5
A30: 铁军薪火：海外新四军抗战档案抢救整理与红色基因传承新范式 | B30: 逐光而行——以京东“阳光天使”为起点的新业态下助残就业新路径 | C30: 稻香菇事——轮作兴农乡村振兴力行者 | D30: 鉴布如飞—新一代柔性全景自增强织造检测高效随诊师 | E30: 信安哨兵——地铁插拔式信号设备智能安全预检系统
A31: 84.73 | B31: 83.41 | C31: 84.13 | D31: 84.51 | E31: 84.77
A32: 第8名 | B32: 第8名 | C32: 第8名 | D32: 第8名 | E32: 第8名
A33: 6 | B33: 3 | C33: 1 | D33: 2 | E33: 6
A34: 有爱无碍，赋能残疾人共享社会发展成果 | B34: 人间重晚晴——守护生命最后一公里的“尊严” | C34: 红途戎耀——退役大学生国防教育赋能计划 | D34: 慧眼鉴晶-晶圆异常针痕及表面缺陷检测领航者 | E34: 藻豆生鲜—新型藻豆复合蛋白基料引领者
A35: 83.21 | B35: 83.16 | C35: 83.09 | D35: 83.79 | E35: 84.27
A36: 第9名 | B36: 第9名 | C36: 第9名 | D36: 第9名 | E36: 第9名
A37: 5 | B37: 2 | C37: 3 | D37: 3 | E37: 2
A38: 铁脉薪传—铁道兵精神传承专列 | B38: 橙光智愿——全国首个铁路志愿全周期赋能学堂 | C38: 忆海拾贝 钿启新航——非遗螺钿的幻彩新生 | D38: 热控凉方——高集成封装芯片散热用高导热界面材料 | E38: 深地之眼—隧洞施工多技术融合智能探测模块践行者
A39: 82.61 | B39: 82.01 | C39: 82.53 | D39: 83 | E39: 83.39
A40: 第10名 | B40: 第10名 | C40: 第10名 | D40: 第10名 | E40: 第10名
...

Sheet 路演答辩顺序
B1: 来源：路演答辩顺序.pdf
A2: 项目名称 | B2: 学校名称 | C2: 参赛赛道 | D2: 参赛组别 | E2: 路演项目组 | F2: 答辩顺序
A3: 地灾卫士--毫米级滑坡灾害监测预警护航者 | B3: 江苏海洋大学 | C3: 高教主赛道 | D3: 本科生创意组 | E3: 高教主赛道本科生创意组1 | F3: 1
A4: 智抗生物——禽病抗体生产源头革新者 | B4: 扬州大学 | C4: 高教主赛道 | D4: 本科生创意组 | E4: 高教主赛道本科生创意组1 | F4: 2
A5: 智巡松宁——国际首创松材线虫病全病程智能监测防控系统 | B5: 南京林业大学 | C5: 高教主赛道 | D5: 本科生创意组 | E5: 高教主赛道本科生创意组1 | F5: 3
A6: “铜”心圆梦——大尺寸高导单晶铜创新性制备解决方案 | B6: 常州大学 | C6: 高教主赛道 | D6: 本科生创意组 | E6: 高教主赛道本科生创意组1 | F6: 4
A7: 蚕安心—智能双效蚕用饲料添加剂领航者 | B7: 江苏科技大学 | C7: 高教主赛道 | D7: 本科生创意组 | E7: 高教主赛道本科生创意组1 | F7: 5
A8: 肾易检—中老年群体居家急性肾损伤早筛仪 | B8: 南京师范大学 | C8: 高教主赛道 | D8: 本科生创意组 | E8: 高教主赛道本科生创意组1 | F8: 6
A9: “壳不容缓”——新能源汽车高安全电池包壳体关键技术创新者 | B9: 扬州职业技术大学 | C9: 高教主赛道 | D9: 本科生创意组 | E9: 高教主赛道本科生创意组1 | F9: 7
A10: 御激神清——ROS响应靶向防治术后认知功能障碍新方案 | B10: 徐州医科大学 | C10: 高教主赛道 | D10: 本科生创意组 | E10: 高教主赛道本科生创意组1 | F10: 8
A11: 叶检先锋——航空发动机复杂曲面叶片智能检测领航者 | B11: 南京理工大学紫金学院 | C11: 高教主赛道 | D11: 本科生创意组 | E11: 高教主赛道本科生创意组1 | F11: 9
A12: “芯”之所“载”——面向双偏振相控阵气象雷达的宽频高动态功率检波芯片 | B12: 南京信息工程大学 | C12: 高教主赛道 | D12: 本科生创意组 | E12: 高教主赛道本科生创意组1 | F12: 10
A13: 追光探微——国产首创超低亮度精密测量亮度计 | B13: 南京理工大学 | C13: 高教主赛道 | D13: 本科生创意组 | E13: 高教主赛道本科生创意组1 | F13: 11
A14: 绿碳纪元——煤炭干法分选产业应用变革的领航者 | B14: 中国矿业大学 | C14: 高教主赛道 | D14: 本科生创意组 | E14: 高教主赛道本科生创意组1 | F14: 12
... A503: IStent—全球首创自膨式可载粒子腔道支架 | B503: 东南大学 | C503: 产业赛道 | D503: 成果转化组 | E503: 产业赛道成果转化组2 | F503: 13

Sheet 数据表
A1: https://jspitcm.woczx.com/event/eventscort/150
A2: https://jspitcm.woczx.com/event/eventscort/151
A3: https://jspitcm.woczx.com/event/eventscort/152
A4: https://jspitcm.woczx.com/event/eventscort/135
A5: https://jspitcm.woczx.com/event/eventscort/136
A7: 进入5个网页（按顺序），然后选择“按得分高低顺序”按钮。接着复制网页比赛得分列表全部内容，到“手动更新”子表，按列顺序粘贴（全选那一列），然后“展示”子表数据就会自动更新。
